[2021-12-16 08:39:16,238] {taskinstance.py:1035} INFO - Dependencies all met for <TaskInstance: pets_dag.create_pet_table manual__2021-12-16T08:39:15.581453+00:00 [queued]>
[2021-12-16 08:39:16,250] {taskinstance.py:1035} INFO - Dependencies all met for <TaskInstance: pets_dag.create_pet_table manual__2021-12-16T08:39:15.581453+00:00 [queued]>
[2021-12-16 08:39:16,250] {taskinstance.py:1241} INFO - 
--------------------------------------------------------------------------------
[2021-12-16 08:39:16,251] {taskinstance.py:1242} INFO - Starting attempt 1 of 1
[2021-12-16 08:39:16,251] {taskinstance.py:1243} INFO - 
--------------------------------------------------------------------------------
[2021-12-16 08:39:16,265] {taskinstance.py:1262} INFO - Executing <Task(PostgresOperator): create_pet_table> on 2021-12-16 08:39:15.581453+00:00
[2021-12-16 08:39:16,271] {standard_task_runner.py:52} INFO - Started process 31576 to run task
[2021-12-16 08:39:16,274] {standard_task_runner.py:76} INFO - Running: ['***', 'tasks', 'run', 'pets_dag', 'create_pet_table', 'manual__2021-12-16T08:39:15.581453+00:00', '--job-id', '49', '--raw', '--subdir', 'DAGS_FOLDER/pets_dag.py', '--cfg-path', '/tmp/tmpmd8cl6jn', '--error-file', '/tmp/tmp0wz4qodi']
[2021-12-16 08:39:16,275] {standard_task_runner.py:77} INFO - Job 49: Subtask create_pet_table
[2021-12-16 08:39:16,320] {logging_mixin.py:109} INFO - Running <TaskInstance: pets_dag.create_pet_table manual__2021-12-16T08:39:15.581453+00:00 [running]> on host 7a5500e9698a
[2021-12-16 08:39:16,374] {taskinstance.py:1429} INFO - Exporting the following env vars:
AIRFLOW_CTX_DAG_OWNER=***
AIRFLOW_CTX_DAG_ID=pets_dag
AIRFLOW_CTX_TASK_ID=create_pet_table
AIRFLOW_CTX_EXECUTION_DATE=2021-12-16T08:39:15.581453+00:00
AIRFLOW_CTX_DAG_RUN_ID=manual__2021-12-16T08:39:15.581453+00:00
[2021-12-16 08:39:16,384] {base.py:79} INFO - Using connection to: id: ***_conn_id. Host: postgres-***, Port: 5432, Schema: , Login: ***, Password: ***, extra: {}
[2021-12-16 08:39:16,388] {dbapi.py:225} INFO - Running statement: -- create hello_world_table
DROP TABLE IF EXISTS pet;
CREATE TABLE pet (
    pet_id SERIAL PRIMARY KEY,
    name VARCHAR NOT NULL,
    pet_type VARCHAR NOT NULL,
    birth_date DATE NOT NULL,
    OWNER VARCHAR NOT NULL
    );, parameters: None
[2021-12-16 14:40:11,920] {taskinstance.py:1029} INFO - Dependencies not met for <TaskInstance: pets_dag.create_pet_table manual__2021-12-16T08:39:15.581453+00:00 [running]>, dependency 'Task Instance State' FAILED: Task is in the 'running' state which is not a valid state for execution. The task must be cleared in order to be run.
[2021-12-16 14:40:11,922] {taskinstance.py:1029} INFO - Dependencies not met for <TaskInstance: pets_dag.create_pet_table manual__2021-12-16T08:39:15.581453+00:00 [running]>, dependency 'Task Instance Not Running' FAILED: Task is in the running state
[2021-12-16 14:40:11,925] {local_task_job.py:99} INFO - Task is not able to be run
[2021-12-19 15:00:44,205] {taskinstance.py:1703} ERROR - Task failed with exception
Traceback (most recent call last):
  File "/home/airflow/.local/lib/python3.7/site-packages/airflow/models/taskinstance.py", line 1332, in _run_raw_task
    self._execute_task_with_callbacks(context)
  File "/home/airflow/.local/lib/python3.7/site-packages/airflow/models/taskinstance.py", line 1458, in _execute_task_with_callbacks
    result = self._execute_task(context, self.task)
  File "/home/airflow/.local/lib/python3.7/site-packages/airflow/models/taskinstance.py", line 1514, in _execute_task
    result = execute_callable(context=context)
  File "/home/airflow/.local/lib/python3.7/site-packages/airflow/providers/postgres/operators/postgres.py", line 69, in execute
    self.hook.run(self.sql, self.autocommit, parameters=self.parameters)
  File "/home/airflow/.local/lib/python3.7/site-packages/airflow/hooks/dbapi.py", line 205, in run
    self._run_command(cur, sql_statement, parameters)
  File "/home/airflow/.local/lib/python3.7/site-packages/airflow/hooks/dbapi.py", line 229, in _run_command
    cur.execute(sql_statement)
psycopg2.errors.AdminShutdown: terminating connection due to administrator command
server closed the connection unexpectedly
	This probably means the server terminated abnormally
	before or while processing the request.

[2021-12-19 15:00:44,278] {taskinstance.py:1280} INFO - Marking task as FAILED. dag_id=pets_dag, task_id=create_pet_table, execution_date=20211216T083915, start_date=20211216T083916, end_date=20211219T150044
[2021-12-19 15:00:44,307] {standard_task_runner.py:91} ERROR - Failed to execute job 49 for task create_pet_table
Traceback (most recent call last):
  File "/home/airflow/.local/lib/python3.7/site-packages/airflow/task/task_runner/standard_task_runner.py", line 85, in _start_by_fork
    args.func(args, dag=self.dag)
  File "/home/airflow/.local/lib/python3.7/site-packages/airflow/cli/cli_parser.py", line 48, in command
    return func(*args, **kwargs)
  File "/home/airflow/.local/lib/python3.7/site-packages/airflow/utils/cli.py", line 92, in wrapper
    return f(*args, **kwargs)
  File "/home/airflow/.local/lib/python3.7/site-packages/airflow/cli/commands/task_command.py", line 292, in task_run
    _run_task_by_selected_method(args, dag, ti)
  File "/home/airflow/.local/lib/python3.7/site-packages/airflow/cli/commands/task_command.py", line 107, in _run_task_by_selected_method
    _run_raw_task(args, ti)
  File "/home/airflow/.local/lib/python3.7/site-packages/airflow/cli/commands/task_command.py", line 184, in _run_raw_task
    error_file=args.error_file,
  File "/home/airflow/.local/lib/python3.7/site-packages/airflow/utils/session.py", line 70, in wrapper
    return func(*args, session=session, **kwargs)
  File "/home/airflow/.local/lib/python3.7/site-packages/airflow/models/taskinstance.py", line 1332, in _run_raw_task
    self._execute_task_with_callbacks(context)
  File "/home/airflow/.local/lib/python3.7/site-packages/airflow/models/taskinstance.py", line 1458, in _execute_task_with_callbacks
    result = self._execute_task(context, self.task)
  File "/home/airflow/.local/lib/python3.7/site-packages/airflow/models/taskinstance.py", line 1514, in _execute_task
    result = execute_callable(context=context)
  File "/home/airflow/.local/lib/python3.7/site-packages/airflow/providers/postgres/operators/postgres.py", line 69, in execute
    self.hook.run(self.sql, self.autocommit, parameters=self.parameters)
  File "/home/airflow/.local/lib/python3.7/site-packages/airflow/hooks/dbapi.py", line 205, in run
    self._run_command(cur, sql_statement, parameters)
  File "/home/airflow/.local/lib/python3.7/site-packages/airflow/hooks/dbapi.py", line 229, in _run_command
    cur.execute(sql_statement)
psycopg2.errors.AdminShutdown: terminating connection due to administrator command
server closed the connection unexpectedly
	This probably means the server terminated abnormally
	before or while processing the request.

[2021-12-19 15:00:44,340] {local_task_job.py:154} INFO - Task exited with return code 1
[2021-12-19 15:00:44,387] {local_task_job.py:264} INFO - 0 downstream tasks scheduled from follow-on schedule check
