[2021-12-20 11:31:51,020] {taskinstance.py:1035} INFO - Dependencies all met for <TaskInstance: run_test_db.test_database manual__2021-12-20T11:31:50.016687+00:00 [queued]>
[2021-12-20 11:31:51,035] {taskinstance.py:1035} INFO - Dependencies all met for <TaskInstance: run_test_db.test_database manual__2021-12-20T11:31:50.016687+00:00 [queued]>
[2021-12-20 11:31:51,036] {taskinstance.py:1241} INFO - 
--------------------------------------------------------------------------------
[2021-12-20 11:31:51,036] {taskinstance.py:1242} INFO - Starting attempt 1 of 1
[2021-12-20 11:31:51,036] {taskinstance.py:1243} INFO - 
--------------------------------------------------------------------------------
[2021-12-20 11:31:51,049] {taskinstance.py:1262} INFO - Executing <Task(PythonOperator): test_database> on 2021-12-20 11:31:50.016687+00:00
[2021-12-20 11:31:51,055] {standard_task_runner.py:52} INFO - Started process 2419 to run task
[2021-12-20 11:31:51,060] {standard_task_runner.py:76} INFO - Running: ['***', 'tasks', 'run', 'run_test_db', 'test_database', 'manual__2021-12-20T11:31:50.016687+00:00', '--job-id', '20', '--raw', '--subdir', 'DAGS_FOLDER/test-mssq-conn.py', '--cfg-path', '/tmp/tmp6hte1s5f', '--error-file', '/tmp/tmpedg6usvy']
[2021-12-20 11:31:51,061] {standard_task_runner.py:77} INFO - Job 20: Subtask test_database
[2021-12-20 11:31:51,107] {logging_mixin.py:109} INFO - Running <TaskInstance: run_test_db.test_database manual__2021-12-20T11:31:50.016687+00:00 [running]> on host 6883114f3a63
[2021-12-20 11:31:51,162] {taskinstance.py:1429} INFO - Exporting the following env vars:
AIRFLOW_CTX_DAG_EMAIL=example@email.com
AIRFLOW_CTX_DAG_OWNER=***
AIRFLOW_CTX_DAG_ID=run_test_db
AIRFLOW_CTX_TASK_ID=test_database
AIRFLOW_CTX_EXECUTION_DATE=2021-12-20T11:31:50.016687+00:00
AIRFLOW_CTX_DAG_RUN_ID=manual__2021-12-20T11:31:50.016687+00:00
[2021-12-20 11:32:51,220] {taskinstance.py:1703} ERROR - Task failed with exception
Traceback (most recent call last):
  File "src/pymssql/_pymssql.pyx", line 646, in pymssql._pymssql.connect
  File "src/pymssql/_mssql.pyx", line 2126, in pymssql._mssql.connect
  File "src/pymssql/_mssql.pyx", line 716, in pymssql._mssql.MSSQLConnection.__init__
  File "src/pymssql/_mssql.pyx", line 1835, in pymssql._mssql.maybe_raise_MSSQLDatabaseException
  File "src/pymssql/_mssql.pyx", line 1852, in pymssql._mssql.raise_MSSQLDatabaseException
pymssql._mssql.MSSQLDatabaseException: (20009, b'DB-Lib error message 20009, severity 9:\nUnable to connect: Adaptive Server is unavailable or does not exist (172.17.0.2)\nNet-Lib error during Connection timed out (110)\nDB-Lib error message 20009, severity 9:\nUnable to connect: Adaptive Server is unavailable or does not exist (172.17.0.2)\nNet-Lib error during Connection timed out (110)\n')

During handling of the above exception, another exception occurred:

Traceback (most recent call last):
  File "/home/airflow/.local/lib/python3.7/site-packages/airflow/models/taskinstance.py", line 1332, in _run_raw_task
    self._execute_task_with_callbacks(context)
  File "/home/airflow/.local/lib/python3.7/site-packages/airflow/models/taskinstance.py", line 1458, in _execute_task_with_callbacks
    result = self._execute_task(context, self.task)
  File "/home/airflow/.local/lib/python3.7/site-packages/airflow/models/taskinstance.py", line 1509, in _execute_task
    result = execute_callable(context=context)
  File "/home/airflow/.local/lib/python3.7/site-packages/airflow/operators/python.py", line 151, in execute
    return_value = self.execute_callable()
  File "/home/airflow/.local/lib/python3.7/site-packages/airflow/operators/python.py", line 162, in execute_callable
    return self.python_callable(*self.op_args, **self.op_kwargs)
  File "/opt/airflow/dags/test-mssq-conn.py", line 23, in test_db
    port="8002") as conn:
  File "src/pymssql/_pymssql.pyx", line 652, in pymssql._pymssql.connect
pymssql._pymssql.OperationalError: (20009, b'DB-Lib error message 20009, severity 9:\nUnable to connect: Adaptive Server is unavailable or does not exist (172.17.0.2)\nNet-Lib error during Connection timed out (110)\nDB-Lib error message 20009, severity 9:\nUnable to connect: Adaptive Server is unavailable or does not exist (172.17.0.2)\nNet-Lib error during Connection timed out (110)\n')
[2021-12-20 11:32:51,234] {taskinstance.py:1280} INFO - Marking task as FAILED. dag_id=run_test_db, task_id=test_database, execution_date=20211220T113150, start_date=20211220T113151, end_date=20211220T113251
[2021-12-20 11:32:51,248] {standard_task_runner.py:91} ERROR - Failed to execute job 20 for task test_database
Traceback (most recent call last):
  File "src/pymssql/_pymssql.pyx", line 646, in pymssql._pymssql.connect
  File "src/pymssql/_mssql.pyx", line 2126, in pymssql._mssql.connect
  File "src/pymssql/_mssql.pyx", line 716, in pymssql._mssql.MSSQLConnection.__init__
  File "src/pymssql/_mssql.pyx", line 1835, in pymssql._mssql.maybe_raise_MSSQLDatabaseException
  File "src/pymssql/_mssql.pyx", line 1852, in pymssql._mssql.raise_MSSQLDatabaseException
pymssql._mssql.MSSQLDatabaseException: (20009, b'DB-Lib error message 20009, severity 9:\nUnable to connect: Adaptive Server is unavailable or does not exist (172.17.0.2)\nNet-Lib error during Connection timed out (110)\nDB-Lib error message 20009, severity 9:\nUnable to connect: Adaptive Server is unavailable or does not exist (172.17.0.2)\nNet-Lib error during Connection timed out (110)\n')

During handling of the above exception, another exception occurred:

Traceback (most recent call last):
  File "/home/airflow/.local/lib/python3.7/site-packages/airflow/task/task_runner/standard_task_runner.py", line 85, in _start_by_fork
    args.func(args, dag=self.dag)
  File "/home/airflow/.local/lib/python3.7/site-packages/airflow/cli/cli_parser.py", line 48, in command
    return func(*args, **kwargs)
  File "/home/airflow/.local/lib/python3.7/site-packages/airflow/utils/cli.py", line 92, in wrapper
    return f(*args, **kwargs)
  File "/home/airflow/.local/lib/python3.7/site-packages/airflow/cli/commands/task_command.py", line 292, in task_run
    _run_task_by_selected_method(args, dag, ti)
  File "/home/airflow/.local/lib/python3.7/site-packages/airflow/cli/commands/task_command.py", line 107, in _run_task_by_selected_method
    _run_raw_task(args, ti)
  File "/home/airflow/.local/lib/python3.7/site-packages/airflow/cli/commands/task_command.py", line 184, in _run_raw_task
    error_file=args.error_file,
  File "/home/airflow/.local/lib/python3.7/site-packages/airflow/utils/session.py", line 70, in wrapper
    return func(*args, session=session, **kwargs)
  File "/home/airflow/.local/lib/python3.7/site-packages/airflow/models/taskinstance.py", line 1332, in _run_raw_task
    self._execute_task_with_callbacks(context)
  File "/home/airflow/.local/lib/python3.7/site-packages/airflow/models/taskinstance.py", line 1458, in _execute_task_with_callbacks
    result = self._execute_task(context, self.task)
  File "/home/airflow/.local/lib/python3.7/site-packages/airflow/models/taskinstance.py", line 1509, in _execute_task
    result = execute_callable(context=context)
  File "/home/airflow/.local/lib/python3.7/site-packages/airflow/operators/python.py", line 151, in execute
    return_value = self.execute_callable()
  File "/home/airflow/.local/lib/python3.7/site-packages/airflow/operators/python.py", line 162, in execute_callable
    return self.python_callable(*self.op_args, **self.op_kwargs)
  File "/opt/airflow/dags/test-mssq-conn.py", line 23, in test_db
    port="8002") as conn:
  File "src/pymssql/_pymssql.pyx", line 652, in pymssql._pymssql.connect
pymssql._pymssql.OperationalError: (20009, b'DB-Lib error message 20009, severity 9:\nUnable to connect: Adaptive Server is unavailable or does not exist (172.17.0.2)\nNet-Lib error during Connection timed out (110)\nDB-Lib error message 20009, severity 9:\nUnable to connect: Adaptive Server is unavailable or does not exist (172.17.0.2)\nNet-Lib error during Connection timed out (110)\n')
[2021-12-20 11:32:51,261] {local_task_job.py:154} INFO - Task exited with return code 1
[2021-12-20 11:32:51,289] {local_task_job.py:264} INFO - 0 downstream tasks scheduled from follow-on schedule check
