[2021-12-13 18:44:01,158] {taskinstance.py:1035} INFO - Dependencies all met for <TaskInstance: postgres_operator_dag.create_pet_table manual__2021-12-13T18:43:59.911541+00:00 [queued]>
[2021-12-13 18:44:01,170] {taskinstance.py:1035} INFO - Dependencies all met for <TaskInstance: postgres_operator_dag.create_pet_table manual__2021-12-13T18:43:59.911541+00:00 [queued]>
[2021-12-13 18:44:01,170] {taskinstance.py:1241} INFO - 
--------------------------------------------------------------------------------
[2021-12-13 18:44:01,170] {taskinstance.py:1242} INFO - Starting attempt 1 of 1
[2021-12-13 18:44:01,170] {taskinstance.py:1243} INFO - 
--------------------------------------------------------------------------------
[2021-12-13 18:44:01,185] {taskinstance.py:1262} INFO - Executing <Task(PostgresOperator): create_pet_table> on 2021-12-13 18:43:59.911541+00:00
[2021-12-13 18:44:01,190] {standard_task_runner.py:52} INFO - Started process 104 to run task
[2021-12-13 18:44:01,194] {standard_task_runner.py:76} INFO - Running: ['***', 'tasks', 'run', 'postgres_operator_dag', 'create_pet_table', 'manual__2021-12-13T18:43:59.911541+00:00', '--job-id', '3', '--raw', '--subdir', 'DAGS_FOLDER/example_postgres.py', '--cfg-path', '/tmp/tmpk9p8tsa0', '--error-file', '/tmp/tmpp5ghjg_x']
[2021-12-13 18:44:01,195] {standard_task_runner.py:77} INFO - Job 3: Subtask create_pet_table
[2021-12-13 18:44:01,241] {logging_mixin.py:109} INFO - Running <TaskInstance: postgres_operator_dag.create_pet_table manual__2021-12-13T18:43:59.911541+00:00 [running]> on host 19493822f754
[2021-12-13 18:44:01,298] {taskinstance.py:1429} INFO - Exporting the following env vars:
AIRFLOW_CTX_DAG_OWNER=***
AIRFLOW_CTX_DAG_ID=postgres_operator_dag
AIRFLOW_CTX_TASK_ID=create_pet_table
AIRFLOW_CTX_EXECUTION_DATE=2021-12-13T18:43:59.911541+00:00
AIRFLOW_CTX_DAG_RUN_ID=manual__2021-12-13T18:43:59.911541+00:00
[2021-12-13 18:44:01,320] {taskinstance.py:1703} ERROR - Task failed with exception
Traceback (most recent call last):
  File "/home/airflow/.local/lib/python3.7/site-packages/airflow/models/taskinstance.py", line 1332, in _run_raw_task
    self._execute_task_with_callbacks(context)
  File "/home/airflow/.local/lib/python3.7/site-packages/airflow/models/taskinstance.py", line 1458, in _execute_task_with_callbacks
    result = self._execute_task(context, self.task)
  File "/home/airflow/.local/lib/python3.7/site-packages/airflow/models/taskinstance.py", line 1514, in _execute_task
    result = execute_callable(context=context)
  File "/home/airflow/.local/lib/python3.7/site-packages/airflow/providers/postgres/operators/postgres.py", line 69, in execute
    self.hook.run(self.sql, self.autocommit, parameters=self.parameters)
  File "/home/airflow/.local/lib/python3.7/site-packages/airflow/hooks/dbapi.py", line 198, in run
    with closing(self.get_conn()) as conn:
  File "/home/airflow/.local/lib/python3.7/site-packages/airflow/providers/postgres/hooks/postgres.py", line 88, in get_conn
    conn = deepcopy(self.connection or self.get_connection(conn_id))
  File "/home/airflow/.local/lib/python3.7/site-packages/airflow/hooks/base.py", line 68, in get_connection
    conn = Connection.get_connection_from_secrets(conn_id)
  File "/home/airflow/.local/lib/python3.7/site-packages/airflow/models/connection.py", line 410, in get_connection_from_secrets
    raise AirflowNotFoundException(f"The conn_id `{conn_id}` isn't defined")
airflow.exceptions.AirflowNotFoundException: The conn_id `***_db` isn't defined
[2021-12-13 18:44:01,328] {taskinstance.py:1280} INFO - Marking task as FAILED. dag_id=postgres_operator_dag, task_id=create_pet_table, execution_date=20211213T184359, start_date=20211213T184401, end_date=20211213T184401
[2021-12-13 18:44:01,344] {standard_task_runner.py:91} ERROR - Failed to execute job 3 for task create_pet_table
Traceback (most recent call last):
  File "/home/airflow/.local/lib/python3.7/site-packages/airflow/task/task_runner/standard_task_runner.py", line 85, in _start_by_fork
    args.func(args, dag=self.dag)
  File "/home/airflow/.local/lib/python3.7/site-packages/airflow/cli/cli_parser.py", line 48, in command
    return func(*args, **kwargs)
  File "/home/airflow/.local/lib/python3.7/site-packages/airflow/utils/cli.py", line 92, in wrapper
    return f(*args, **kwargs)
  File "/home/airflow/.local/lib/python3.7/site-packages/airflow/cli/commands/task_command.py", line 292, in task_run
    _run_task_by_selected_method(args, dag, ti)
  File "/home/airflow/.local/lib/python3.7/site-packages/airflow/cli/commands/task_command.py", line 107, in _run_task_by_selected_method
    _run_raw_task(args, ti)
  File "/home/airflow/.local/lib/python3.7/site-packages/airflow/cli/commands/task_command.py", line 184, in _run_raw_task
    error_file=args.error_file,
  File "/home/airflow/.local/lib/python3.7/site-packages/airflow/utils/session.py", line 70, in wrapper
    return func(*args, session=session, **kwargs)
  File "/home/airflow/.local/lib/python3.7/site-packages/airflow/models/taskinstance.py", line 1332, in _run_raw_task
    self._execute_task_with_callbacks(context)
  File "/home/airflow/.local/lib/python3.7/site-packages/airflow/models/taskinstance.py", line 1458, in _execute_task_with_callbacks
    result = self._execute_task(context, self.task)
  File "/home/airflow/.local/lib/python3.7/site-packages/airflow/models/taskinstance.py", line 1514, in _execute_task
    result = execute_callable(context=context)
  File "/home/airflow/.local/lib/python3.7/site-packages/airflow/providers/postgres/operators/postgres.py", line 69, in execute
    self.hook.run(self.sql, self.autocommit, parameters=self.parameters)
  File "/home/airflow/.local/lib/python3.7/site-packages/airflow/hooks/dbapi.py", line 198, in run
    with closing(self.get_conn()) as conn:
  File "/home/airflow/.local/lib/python3.7/site-packages/airflow/providers/postgres/hooks/postgres.py", line 88, in get_conn
    conn = deepcopy(self.connection or self.get_connection(conn_id))
  File "/home/airflow/.local/lib/python3.7/site-packages/airflow/hooks/base.py", line 68, in get_connection
    conn = Connection.get_connection_from_secrets(conn_id)
  File "/home/airflow/.local/lib/python3.7/site-packages/airflow/models/connection.py", line 410, in get_connection_from_secrets
    raise AirflowNotFoundException(f"The conn_id `{conn_id}` isn't defined")
airflow.exceptions.AirflowNotFoundException: The conn_id `***_db` isn't defined
[2021-12-13 18:44:01,366] {local_task_job.py:154} INFO - Task exited with return code 1
[2021-12-13 18:44:01,410] {local_task_job.py:264} INFO - 0 downstream tasks scheduled from follow-on schedule check
