[2021-12-13 19:21:44,219] {taskinstance.py:1035} INFO - Dependencies all met for <TaskInstance: postgres_operator_dag.get_all_pets manual__2021-12-13T19:21:41.655886+00:00 [queued]>
[2021-12-13 19:21:44,229] {taskinstance.py:1035} INFO - Dependencies all met for <TaskInstance: postgres_operator_dag.get_all_pets manual__2021-12-13T19:21:41.655886+00:00 [queued]>
[2021-12-13 19:21:44,229] {taskinstance.py:1241} INFO - 
--------------------------------------------------------------------------------
[2021-12-13 19:21:44,229] {taskinstance.py:1242} INFO - Starting attempt 1 of 1
[2021-12-13 19:21:44,230] {taskinstance.py:1243} INFO - 
--------------------------------------------------------------------------------
[2021-12-13 19:21:44,241] {taskinstance.py:1262} INFO - Executing <Task(PostgresOperator): get_all_pets> on 2021-12-13 19:21:41.655886+00:00
[2021-12-13 19:21:44,246] {standard_task_runner.py:52} INFO - Started process 332 to run task
[2021-12-13 19:21:44,250] {standard_task_runner.py:76} INFO - Running: ['***', 'tasks', 'run', 'postgres_operator_dag', 'get_all_pets', 'manual__2021-12-13T19:21:41.655886+00:00', '--job-id', '6', '--raw', '--subdir', 'DAGS_FOLDER/example_postgres.py', '--cfg-path', '/tmp/tmpw851ll2m', '--error-file', '/tmp/tmpen5zuzc_']
[2021-12-13 19:21:44,250] {standard_task_runner.py:77} INFO - Job 6: Subtask get_all_pets
[2021-12-13 19:21:44,291] {logging_mixin.py:109} INFO - Running <TaskInstance: postgres_operator_dag.get_all_pets manual__2021-12-13T19:21:41.655886+00:00 [running]> on host ef07609851a1
[2021-12-13 19:21:44,342] {taskinstance.py:1429} INFO - Exporting the following env vars:
AIRFLOW_CTX_DAG_OWNER=***
AIRFLOW_CTX_DAG_ID=postgres_operator_dag
AIRFLOW_CTX_TASK_ID=get_all_pets
AIRFLOW_CTX_EXECUTION_DATE=2021-12-13T19:21:41.655886+00:00
AIRFLOW_CTX_DAG_RUN_ID=manual__2021-12-13T19:21:41.655886+00:00
[2021-12-13 19:21:44,363] {taskinstance.py:1703} ERROR - Task failed with exception
Traceback (most recent call last):
  File "/home/airflow/.local/lib/python3.7/site-packages/airflow/models/taskinstance.py", line 1332, in _run_raw_task
    self._execute_task_with_callbacks(context)
  File "/home/airflow/.local/lib/python3.7/site-packages/airflow/models/taskinstance.py", line 1458, in _execute_task_with_callbacks
    result = self._execute_task(context, self.task)
  File "/home/airflow/.local/lib/python3.7/site-packages/airflow/models/taskinstance.py", line 1514, in _execute_task
    result = execute_callable(context=context)
  File "/home/airflow/.local/lib/python3.7/site-packages/airflow/providers/postgres/operators/postgres.py", line 69, in execute
    self.hook.run(self.sql, self.autocommit, parameters=self.parameters)
  File "/home/airflow/.local/lib/python3.7/site-packages/airflow/hooks/dbapi.py", line 198, in run
    with closing(self.get_conn()) as conn:
  File "/home/airflow/.local/lib/python3.7/site-packages/airflow/providers/postgres/hooks/postgres.py", line 88, in get_conn
    conn = deepcopy(self.connection or self.get_connection(conn_id))
  File "/home/airflow/.local/lib/python3.7/site-packages/airflow/hooks/base.py", line 68, in get_connection
    conn = Connection.get_connection_from_secrets(conn_id)
  File "/home/airflow/.local/lib/python3.7/site-packages/airflow/models/connection.py", line 410, in get_connection_from_secrets
    raise AirflowNotFoundException(f"The conn_id `{conn_id}` isn't defined")
airflow.exceptions.AirflowNotFoundException: The conn_id `postgres_default` isn't defined
[2021-12-13 19:21:44,371] {taskinstance.py:1280} INFO - Marking task as FAILED. dag_id=postgres_operator_dag, task_id=get_all_pets, execution_date=20211213T192141, start_date=20211213T192144, end_date=20211213T192144
[2021-12-13 19:21:44,385] {standard_task_runner.py:91} ERROR - Failed to execute job 6 for task get_all_pets
Traceback (most recent call last):
  File "/home/airflow/.local/lib/python3.7/site-packages/airflow/task/task_runner/standard_task_runner.py", line 85, in _start_by_fork
    args.func(args, dag=self.dag)
  File "/home/airflow/.local/lib/python3.7/site-packages/airflow/cli/cli_parser.py", line 48, in command
    return func(*args, **kwargs)
  File "/home/airflow/.local/lib/python3.7/site-packages/airflow/utils/cli.py", line 92, in wrapper
    return f(*args, **kwargs)
  File "/home/airflow/.local/lib/python3.7/site-packages/airflow/cli/commands/task_command.py", line 292, in task_run
    _run_task_by_selected_method(args, dag, ti)
  File "/home/airflow/.local/lib/python3.7/site-packages/airflow/cli/commands/task_command.py", line 107, in _run_task_by_selected_method
    _run_raw_task(args, ti)
  File "/home/airflow/.local/lib/python3.7/site-packages/airflow/cli/commands/task_command.py", line 184, in _run_raw_task
    error_file=args.error_file,
  File "/home/airflow/.local/lib/python3.7/site-packages/airflow/utils/session.py", line 70, in wrapper
    return func(*args, session=session, **kwargs)
  File "/home/airflow/.local/lib/python3.7/site-packages/airflow/models/taskinstance.py", line 1332, in _run_raw_task
    self._execute_task_with_callbacks(context)
  File "/home/airflow/.local/lib/python3.7/site-packages/airflow/models/taskinstance.py", line 1458, in _execute_task_with_callbacks
    result = self._execute_task(context, self.task)
  File "/home/airflow/.local/lib/python3.7/site-packages/airflow/models/taskinstance.py", line 1514, in _execute_task
    result = execute_callable(context=context)
  File "/home/airflow/.local/lib/python3.7/site-packages/airflow/providers/postgres/operators/postgres.py", line 69, in execute
    self.hook.run(self.sql, self.autocommit, parameters=self.parameters)
  File "/home/airflow/.local/lib/python3.7/site-packages/airflow/hooks/dbapi.py", line 198, in run
    with closing(self.get_conn()) as conn:
  File "/home/airflow/.local/lib/python3.7/site-packages/airflow/providers/postgres/hooks/postgres.py", line 88, in get_conn
    conn = deepcopy(self.connection or self.get_connection(conn_id))
  File "/home/airflow/.local/lib/python3.7/site-packages/airflow/hooks/base.py", line 68, in get_connection
    conn = Connection.get_connection_from_secrets(conn_id)
  File "/home/airflow/.local/lib/python3.7/site-packages/airflow/models/connection.py", line 410, in get_connection_from_secrets
    raise AirflowNotFoundException(f"The conn_id `{conn_id}` isn't defined")
airflow.exceptions.AirflowNotFoundException: The conn_id `postgres_default` isn't defined
[2021-12-13 19:21:44,421] {local_task_job.py:154} INFO - Task exited with return code 1
[2021-12-13 19:21:44,463] {local_task_job.py:264} INFO - 0 downstream tasks scheduled from follow-on schedule check
